#### Promise

> jest会等待Prose的resolve状态,如果**返回的是reject将会测试失败**

```js
test('the data is peanut butter', () => {
  return fetchData().then(data => {
    expect(data).toBe('peanut butter');
  });
});
```

#### async/await

> 测试具有async/await代码时,可以在**test函数的第二参数前面写上async**,就可以来测试async/await

```js
																//async
test('the data is peanut butter', async () => {
  const data = await fetchData();
  expect(data).toBe('peanut butter');
});
```

> 也可以将 `async` and `await`和 `.resolves` or `.rejects`一起使用

```js
test('the data is peanut butter', async () => {
  await expect(fetchData()).resolves.toBe('peanut butter');
});
```

#### expect.assertions(number)

> 断言,常用于在异步函数中保证有n个回调被调用了

```js
expect.assertions(1);
//保证有一个回调用调用
```

#### 期望promise倍reject

> 如果期望Promise被Reject，则需要使用 `.catch` 方法,确保添加 `expect.assertions` 来验证一定数量的断言被调用

```js
test('the fetch fails with an error', () => {
  expect.assertions(1);
  return fetchData().catch(e => expect(e).toMatch('error'));
});
```

#### 回调方式

##### 错误

> 默认情况下,代码执行一旦到达上下文底部jest测试就会结束

```js
// 不要这样做！！！
test('the data is peanut butter', () => {
  function callback(error, data) {
    if (error) {
      throw error;
    }
    expect(data).toBe('peanut butter');
  }

  fetchData(callback);
});
```

##### 方法1:正确方式使用done()函数

> jest会得到done()函数被调用会才会结束

> 若 `done()` 函数**从未被调用**，测试用例会正如你预期的那样**执行失败（显示超时错误)**

> 若 `expect` **执行失败**，它会抛出一个**错误**，后面的 `done()` **不再执行**

> 若想要知道失败的理由,就需要使用try...catch

```js
test('the data is peanut butter', done => {
  function callback(error, data) {
    if (error) {
      done(error);
      return;
    }
    try {
      expect(data).toBe('peanut butter');
      done();
    } catch (error) {
      done(error);
    }
  }

  fetchData(callback);
});
```

##### 注意： `done()` 不应与Promises混合，因为这会导致您测试中的内存泄漏。

##### 方法2:.resolves()/.rejects

> 使用 `.resolves` 匹配器在您期望的声明,如果 Promise 被**拒绝**，则测试将自动失败

```js
test('the data is peanut butter', () => {
  return expect(fetchData()).resolves.toBe('peanut butter');
});
```

> 使用 `.rejects` 匹配器,如果 Promise 被**成功**，则测试将自动失败

```js
test('the fetch fails with an error', () => {
  return expect(fetchData()).rejects.toMatch('error');
});
```

###### 注意:一定要把整个断言return出去,如果没有return,那么`fetchData`返回的这个promise状态变为resolved,还没有等后面的执行,测试就已经被视为已经完成了